[2024-11-12T09:00:47.705+0000] {local_task_job_runner.py:120} INFO - ::group::Pre task execution logs
[2024-11-12T09:00:47.755+0000] {taskinstance.py:2076} INFO - Dependencies all met for dep_context=non-requeueable deps ti=<TaskInstance: nyc_green_taxi.transform_data_task manual__2024-11-12T08:55:18.847308+00:00 [queued]>
[2024-11-12T09:00:47.775+0000] {taskinstance.py:2076} INFO - Dependencies all met for dep_context=requeueable deps ti=<TaskInstance: nyc_green_taxi.transform_data_task manual__2024-11-12T08:55:18.847308+00:00 [queued]>
[2024-11-12T09:00:47.776+0000] {taskinstance.py:2306} INFO - Starting attempt 2 of 2
[2024-11-12T09:00:47.822+0000] {taskinstance.py:2330} INFO - Executing <Task(PythonOperator): transform_data_task> on 2024-11-12 08:55:18.847308+00:00
[2024-11-12T09:00:47.835+0000] {standard_task_runner.py:64} INFO - Started process 279 to run task
[2024-11-12T09:00:47.849+0000] {standard_task_runner.py:90} INFO - Running: ['***', 'tasks', 'run', 'nyc_green_taxi', 'transform_data_task', 'manual__2024-11-12T08:55:18.847308+00:00', '--job-id', '17', '--raw', '--subdir', 'DAGS_FOLDER/data_ingestion.py', '--cfg-path', '/tmp/tmp7hmgs5ib']
[2024-11-12T09:00:47.856+0000] {standard_task_runner.py:91} INFO - Job 17: Subtask transform_data_task
[2024-11-12T09:00:47.967+0000] {task_command.py:426} INFO - Running <TaskInstance: nyc_green_taxi.transform_data_task manual__2024-11-12T08:55:18.847308+00:00 [running]> on host 23d8db8c711b
[2024-11-12T09:00:48.202+0000] {taskinstance.py:2648} INFO - Exporting env vars: AIRFLOW_CTX_DAG_EMAIL='muhii.smta@gmail.com' AIRFLOW_CTX_DAG_OWNER='Muhii' AIRFLOW_CTX_DAG_ID='nyc_green_taxi' AIRFLOW_CTX_TASK_ID='transform_data_task' AIRFLOW_CTX_EXECUTION_DATE='2024-11-12T08:55:18.847308+00:00' AIRFLOW_CTX_TRY_NUMBER='2' AIRFLOW_CTX_DAG_RUN_ID='manual__2024-11-12T08:55:18.847308+00:00'
[2024-11-12T09:00:48.204+0000] {taskinstance.py:430} INFO - ::endgroup::
[2024-11-12T09:00:48.466+0000] {taskinstance.py:441} INFO - ::group::Post task execution logs
[2024-11-12T09:00:48.474+0000] {taskinstance.py:2905} ERROR - Task failed with exception
Traceback (most recent call last):
  File "/home/airflow/.local/lib/python3.9/site-packages/pandas/core/indexes/base.py", line 3791, in get_loc
    return self._engine.get_loc(casted_key)
  File "index.pyx", line 152, in pandas._libs.index.IndexEngine.get_loc
  File "index.pyx", line 181, in pandas._libs.index.IndexEngine.get_loc
  File "pandas/_libs/hashtable_class_helper.pxi", line 7080, in pandas._libs.hashtable.PyObjectHashTable.get_item
  File "pandas/_libs/hashtable_class_helper.pxi", line 7088, in pandas._libs.hashtable.PyObjectHashTable.get_item
KeyError: 'lpep _pickup_datetime'

The above exception was the direct cause of the following exception:

Traceback (most recent call last):
  File "/home/airflow/.local/lib/python3.9/site-packages/airflow/models/taskinstance.py", line 465, in _execute_task
    result = _execute_callable(context=context, **execute_callable_kwargs)
  File "/home/airflow/.local/lib/python3.9/site-packages/airflow/models/taskinstance.py", line 432, in _execute_callable
    return execute_callable(context=context, **execute_callable_kwargs)
  File "/home/airflow/.local/lib/python3.9/site-packages/airflow/models/baseoperator.py", line 401, in wrapper
    return func(self, *args, **kwargs)
  File "/home/airflow/.local/lib/python3.9/site-packages/airflow/operators/python.py", line 235, in execute
    return_value = self.execute_callable()
  File "/home/airflow/.local/lib/python3.9/site-packages/airflow/operators/python.py", line 252, in execute_callable
    return self.python_callable(*self.op_args, **self.op_kwargs)
  File "/opt/airflow/dags/data_ingestion.py", line 58, in transform
    df['lpep_pickup_datetime'] = pd.to_datetime(df['lpep _pickup_datetime'], errors='coerce')
  File "/home/airflow/.local/lib/python3.9/site-packages/pandas/core/frame.py", line 3893, in __getitem__
    indexer = self.columns.get_loc(key)
  File "/home/airflow/.local/lib/python3.9/site-packages/pandas/core/indexes/base.py", line 3798, in get_loc
    raise KeyError(key) from err
KeyError: 'lpep _pickup_datetime'
[2024-11-12T09:00:48.528+0000] {taskinstance.py:1206} INFO - Marking task as FAILED. dag_id=nyc_green_taxi, task_id=transform_data_task, run_id=manual__2024-11-12T08:55:18.847308+00:00, execution_date=20241112T085518, start_date=20241112T090047, end_date=20241112T090048
[2024-11-12T09:00:48.567+0000] {standard_task_runner.py:110} ERROR - Failed to execute job 17 for task transform_data_task ('lpep _pickup_datetime'; 279)
[2024-11-12T09:00:48.666+0000] {local_task_job_runner.py:243} INFO - Task exited with return code 1
[2024-11-12T09:00:48.702+0000] {local_task_job_runner.py:222} INFO - ::endgroup::
